Workbook

Sheet Filtered Data
A1: Player | B1: 2025 Salary | C1: Years in the league | D1: 2025 Status | E1: 2025 Signing | F1: G | G1: MIN | H1: PER | I1: PER*Min | J1: WS | K1: Off WS | L1: Def WS | M1: WS/40 | N1: Off WS/40 | O1: Def WS/40 | P1: Player Off Rtg | Q1: Player Def Rtg
A2: Kelsey Mitchell | B2: 269244 | C2: 8 | D2: Supermax | E2: Core | F2: 44 | G2: 1381 | H2: 20 | I2: 27655 | J2: 5.6 | K2: 4.8 | L2: 0.8 | M2: 0.16 | N2: 0.14 | O2: 0.02 | P2: 114 | Q2: 105.4
A3: Arike Ogunbowale | B3: 249032 | C3: 7 | D3: Standard Max | E3: -- | F3: 29 | G3: 966 | H3: 13.3 | I3: 12825 | J3: 1.3 | K3: 1.3 | L3: 0 | M3: 0.05 | N3: 0.05 | O3: 0 | P3: 101.8 | Q3: 110
A4: Jewell Loyd | B4: 249032 | C4: 11 | D4: Standard Max | E4: Core | F4: 44 | G4: 1245 | H4: 13.4 | I4: 16739 | J4: 2.9 | K4: 2 | L4: 1 | M4: 0.09 | N4: 0.06 | O4: 0.03 | P4: 106.5 | Q4: 104
A5: Kahleah Copper | B5: 248134 | C5: 10 | D5: Standard Max | E5: Core | F5: 28 | G5: 752 | H5: 14.7 | I5: 11094 | J5: 1.5 | K5: 0.8 | L5: 0.8 | M5: 0.08 | N5: 0.04 | O5: 0.04 | P5: 98.4 | Q5: 101.8
A6: Gabby Williams | B6: 225000 | C6: 8 | D6: Standard Max | E6: Core | F6: 44 | G6: 1391 | H6: 15.6 | I6: 21728 | J6: 3.5 | K6: 1.3 | L6: 2.2 | M6: 0.1 | N6: 0.04 | O6: 0.06 | P6: 99.6 | Q6: 97.3
A7: Ariel Atkins | B7: 223000 | C7: 8 | D7: Standard Max | E7: -- | F7: 34 | G7: 970 | H7: 16 | I7: 15499 | J7: 2 | K7: 1.5 | L7: 0.4 | M7: 0.08 | N7: 0.06 | O7: 0.02 | P7: 103.6 | Q7: 106.5
A8: Breanna Stewart | B8: 222400 | C8: 10 | D8: Standard Max | E8: Core | F8: 31 | G8: 948 | H8: 23.7 | I8: 22486 | J8: 4.7 | K8: 3.2 | L8: 1.5 | M8: 0.2 | N8: 0.13 | O8: 0.07 | P8: 112.6 | Q8: 97.3
A9: Sabrina Ionescu | B9: 222060 | C9: 6 | D9: Standard Max | E9: Rookie | F9: 38 | G9: 1194 | H9: 20.6 | I9: 24600 | J9: 4.5 | K9: 3.2 | L9: 1.3 | M9: 0.15 | N9: 0.11 | O9: 0.04 | P9: 107 | Q9: 101.3
A10: Alyssa Thomas | B10: 215000 | C10: 12 | D10: Standard Max | E10: Core | F10: 39 | G10: 1221 | H10: 25.1 | I10: 30588 | J10: 6.6 | K10: 4.4 | L10: 2.2 | M10: 0.22 | N10: 0.14 | O10: 0.07 | P10: 113.5 | Q10: 95.7
A11: Satou Sabally | B11: 215000 | C11: 6 | D11: Standard Max | E11: Core | F11: 39 | G11: 1039 | H11: 19.6 | I11: 20393 | J11: 4 | K11: 2.4 | L11: 1.6 | M11: 0.15 | N11: 0.09 | O11: 0.06 | P11: 105.5 | Q11: 98.1
A12: Brionna Jones | B12: 214466 | C12: 9 | D12: Standard Max | E12: UFA | F12: 44 | G12: 1169 | H12: 22.4 | I12: 26216 | J12: 6.3 | K12: 4.2 | L12: 2.1 | M12: 0.22 | N12: 0.14 | O12: 0.07 | P12: 119.1 | Q12: 95.9
A13: Brittney Griner | B13: 214466 | C13: 13 | D13: Standard Max | E13: UFA | F13: 39 | G13: 810 | H13: 16.2 | I13: 13154 | J13: 2.4 | K13: 1.1 | L13: 1.4 | M13: 0.12 | N13: 0.05 | O13: 0.07 | P13: 102.1 | Q13: 96.6
... A40: Jackie Young | B40: 169950 | C40: 7 | D40: Mid-tier Veteran | E40: -- | F40: 44 | G40: 1336 | H40: 22.1 | I40: 29572 | J40: 6.3 | K40: 5 | L40: 1.3 | M40: 0.19 | N40: 0.15 | O40: 0.04 | P40: 116.9 | Q40: 102.5
A41: Stephanie Talbot | B41: =125000+35110 -> 160110 | C41: 8 | D41: Mid-tier Veteran | E41: UFA | F41: 38 | G41: 541 | H41: 9.1 | I41: 4920 | J41: 0.7 | K41: 0.1 | L41: 0.6 | M41: 0.05 | N41: 0.01 | O41: 0.04 | P41: 94.5 | Q41: 101.4
A42: Rebecca Allen | B42: 160000 | C42: 10 | D42: Mid-tier Veteran | E42: UFA | F42: 44 | G42: 821 | H42: 7.9 | I42: 6497 | J42: 0 | K42: -0.1 | L42: 0.2 | M42: 0 | N42: -0.01 | O42: 0.01 | P42: 90.2 | Q42: 108.6
A43: Alanna Smith | B43: 150000 | C43: 7 | D43: Mid-tier Veteran | E43: UFA | F43: 42 | G43: 1114 | H43: 18 | I43: 20095 | J43: 4.5 | K43: 2.2 | L43: 2.3 | M43: 0.16 | N43: 0.08 | O43: 0.08 | P43: 110 | Q43: 93.7
A44: Nia Coffey | B44: 150000 | C44: 9 | D44: Mid-tier Veteran | E44: UFA | F44: 44 | G44: 455 | H44: 14.1 | I44: 6402 | J44: 1.4 | K44: 0.6 | L44: 0.8 | M44: 0.12 | N44: 0.05 | O44: 0.07 | P44: 102.7 | Q44: 96.4
A45: Shatori Walker-Kimbrough | B45: 150000 | C45: 10 | D45: Mid-tier Veteran | E45: UFA | F45: 41 | G45: 354 | H45: 7.8 | I45: 2759 | J45: 0.6 | K45: 0.1 | L45: 0.5 | M45: 0.07 | N45: 0.01 | O45: 0.06 | P45: 97.5 | Q45: 99
A46: Moriah Jefferson | B46: 145500 | C46: 10 | D46: Mid-tier Veteran | E46: UFA | F46: 5 | G46: 35 | H46: 9.3 | I46: 327000 | J46: 0 | K46: 0 | L46: 0 | M46: 0.03 | N46: 0.04 | O46: -0.01 | P46: 104.7 | Q46: 112
A47: Kia Nurse | B47: 145000 | C47: 8 | D47: Mid-tier Veteran | E47: UFA | F47: 44 | G47: 962 | H47: 7.3 | I47: 7004 | J47: 0 | K47: 0.3 | L47: -0.3 | M47: 0 | N47: 0.01 | O47: -0.01 | P47: 95.2 | Q47: 112.5
A48: Rae Burrell | B48: 137500 | C48: 5 | D48: Mid-tier Veteran | E48: UFA | F48: 28 | G48: 515 | H48: 13 | I48: 6719 | J48: 0.7 | K48: 0.7 | L48: 0 | M48: 0.06 | N48: 0.06 | O48: 0 | P48: 104.5 | Q48: 110.1
A49: DeWanna Bonner | B49: =72269+63721 -> 135990 | C49: 17 | D49: Veteran Minimum | E49: UFA | F49: 33 | G49: 778 | H49: 15.2 | I49: 11865 | J49: 2.6 | K49: 1.6 | L49: 1 | M49: 0.13 | N49: 0.08 | O49: 0.05 | P49: 111.1 | Q49: 100.2
A50: Natisha Hiedeman | B50: 135000 | C50: 7 | D50: Mid-tier Veteran | E50: UFA | F50: 44 | G50: 833 | H50: 18.1 | I50: 15031 | J50: 3.4 | K50: 2.4 | L50: 1.1 | M50: 0.16 | N50: 0.11 | O50: 0.05 | P50: 114 | Q50: 100.1
A51: Kayla Thornton | B51: 132000 | C51: 10 | D51: Mid-tier Veteran | E51: -- | F51: 22 | G51: 662 | H51: 15.1 | I51: 10006 | J51: 1.9 | K51: 0.8 | L51: 1.1 | M51: 0.11 | N51: 0.05 | O51: 0.07 | P51: 100.5 | Q51: 97
A52: Kalani Brown | B52: 128750 | C52: 7 | D52: Mid-tier Veteran | E52: UFA | F52: 29 | G52: 370 | H52: 18.6 | I52: 6903 | J52: 1.6 | K52: 1 | L52: 0.6 | M52: 0.17 | N52: 0.11 | O52: 0.06 | P52: 119 | Q52: 97.5
A53: Bridget Carleton | B53: 125000 | C53: 7 | D53: Mid-tier Veteran | E53: UFA | F53: 44 | G53: 1227 | H53: 10 | I53: 12270 | J53: 3.2 | K53: 1.7 | L53: 1.5 | M53: 0.1 | N53: 0.06 | O53: 0.05 | P53: 112.2 | Q53: 100.7
A54: Michaela Onyenwere | B54: 125000 | C54: 5 | D54: Mid-tier Veteran | E54: RFA | F54: 42 | G54: 711 | H54: 8 | I54: 5654 | J54: 0 | K54: 0.2 | L54: -0.2 | M54: 0 | N54: 0.01 | O54: -0.01 | P54: 94.3 | Q54: 111.8
A55: Sami Whitcomb | B55: 125000 | C55: 9 | D55: Mid-tier Veteran | E55: UFA | F55: 43 | G55: 1027 | H55: 11.5 | I55: 11850 | J55: 2.1 | K55: 1.1 | L55: 1 | M55: 0.08 | N55: 0.04 | O55: 0.04 | P55: 101.7 | Q55: 102.7
A56: Karlie Samuelson | B56: 118450 | C56: 9 | D56: Mid-tier Veteran | E56: UFA | F56: 16 | G56: 228 | H56: 6.7 | I56: 1526 | J56: 0.5 | K56: 0.2 | L56: 0.3 | M56: 0.09 | N56: 0.04 | O56: 0.05 | P56: 104.4 | Q56: 100
A57: Emma Cannon | B57: 116331 | C57: 5 | D57: Mid-tier Veteran | E57: UFA | F57: 21 | G57: 213 | H57: 13.6 | I57: 2893 | J57: 0.4 | K57: 0.4 | L57: 0.1 | M57: 0.08 | N57: 0.07 | O57: 0.01 | P57: 107.5 | Q57: 107.4
A58: Natasha Mack | B58: 116079 | C58: 5 | D58: Mid-tier Veteran | E58: Reserved | F58: 34 | G58: 623 | H58: 19.1 | I58: 11920 | J58: 2.8 | K58: 1.5 | L58: 1.3 | M58: 0.18 | N58: 0.1 | O58: 0.09 | P58: 124.8 | Q58: 93.3
A59: Monique Billings | B59: 110000 | C59: 8 | D59: Mid-tier Veteran | E59: UFA | F59: 26 | G59: 474 | H59: 16.7 | I59: 7916 | J59: 1.7 | K59: 0.8 | L59: 0.8 | M59: 0.14 | N59: 0.07 | O59: 0.07 | P59: 107.7 | Q59: 96.2
A60: Veronica Burton | B60: 103831 | C60: 4 | D60: Mid-tier Veteran | E60: UFA | F60: 44 | G60: 1292 | H60: 19 | I60: 24566 | J60: 6.1 | K60: 4.3 | L60: 1.8 | M60: 0.19 | N60: 0.13 | O60: 0.06 | P60: 117.1 | Q60: 99.1
A61: Kiah Stokes | B61: 103000 | C61: 10 | D61: Mid-tier Veteran | E61: UFA | F61: 40 | G61: 514 | H61: 7 | I61: 3587 | J61: 0.7 | K61: 0 | L61: 0.7 | M61: 0.06 | N61: 0 | O61: 0.06 | P61: 91.8 | Q61: 98.9
... A70: Sug Sutton | B70: 93831 | C70: 4 | D70: Mid-tier Veteran | E70: Reserved | F70: 43 | G70: 1122 | H70: 9.8 | I70: 11051 | J70: 1.1 | K70: 0.5 | L70: 0.6 | M70: 0.04 | N70: 0.02 | O70: 0.02 | P70: 96.5 | Q70: 106.1
A71: Yvonne Anderson | B71: =85000+7774 -> 92774 | C71: 12 | D71: Mid-tier Veteran | E71: UFA | F71: 1 | G71: 12 | H71: 1.1 | I71: 13000 | J71: 0 | K71: 0 | L71: 0 | M71: 0.01 | N71: -0.11 | O71: 0.12 | P71: 50.2 | Q71: 86.5
A72: NaLyssa Smith | B72: 91981 | C72: 4 | D72: Rookie Scale | E72: Rookie | F72: 45 | G72: 956 | H72: 13.2 | I72: 12601 | J72: 2.3 | K72: 1.3 | L72: 0.9 | M72: 0.09 | N72: 0.06 | O72: 0.04 | P72: 105.6 | Q72: 102.4
A73: Rhyne Howard | B73: 91981 | C73: 4 | D73: Rookie Scale | E73: Rookie | F73: 33 | G73: 1151 | H73: 18.2 | I73: 20907 | J73: 4.9 | K73: 3.1 | L73: 1.8 | M73: 0.17 | N73: 0.11 | O73: 0.06 | P73: 111 | Q73: 97.6
A74: Shakira Austin | B74: 91981 | C74: 4 | D74: Rookie Scale | E74: Rookie | F74: 38 | G74: 874 | H74: 18.5 | I74: 16164 | J74: 1.6 | K74: 0.2 | L74: 1.5 | M74: 0.07 | N74: 0.01 | O74: 0.07 | P74: 92.9 | Q74: 96.8
...

Sheet Analysis
A1: Status count | D1: What-if scenarios of underpaid players
A2: Status | B2: Total | D2: Player | E2: Salary tier | F2: PER | G2: Adjusted salary tier
A3: Supermax | B3: =COUNTIF('Filtered Data'!D:D, A3) -> 1 | D3: {=_xlfn._xlws.FILTER('Filtered Data'!A2:A183, ('Filtered Data'!B2:B183<80336) * ('Filtered Data'!H2:H183>=13))} -> Nyara Sabally | E3: {=_xlfn._xlws.FILTER('Filtered Data'!D2:D183, ('Filtered Data'!B2:B183<80336) * ('Filtered Data'!H2:H183>=13))} -> Rookie Scale | F3: {=_xlfn._xlws.FILTER('Filtered Data'!H2:H183, ('Filtered Data'!B2:B183<80336) * ('Filtered Data'!H2:H183>=13))} -> 13.4 | G3: =IF(F3>=25, "Super Max", IF(F3>=20, "Standard Max", IF(F3>=13, "Mid-tier", "Below Mid-tier"))) -> Mid-tier
A4: Standard Max | B4: =COUNTIF('Filtered Data'!D:D, A4) -> 13 | D4: Cheyenne Parker-Tyus | E4: Veteran Minimum | F4: 37.6 | G4: =IF(F4>=25, "Super Max", IF(F4>=20, "Standard Max", IF(F4>=13, "Mid-tier", "Below Mid-tier"))) -> Super Max
A5: Mid-tier Veteran | B5: =COUNTIF('Filtered Data'!D:D, A5) -> 63 | D5: Dominique Malonga | E5: Rookie Scale | F5: 20.1 | G5: =IF(F5>=25, "Super Max", IF(F5>=20, "Standard Max", IF(F5>=13, "Mid-tier", "Below Mid-tier"))) -> Standard Max
A6: Veteran Minimum | B6: =COUNTIF('Filtered Data'!D:D, A6) -> 13 | D6: Erica Wheeler | E6: Veteran Minimum | F6: 13.3 | G6: =IF(F6>=25, "Super Max", IF(F6>=20, "Standard Max", IF(F6>=13, "Mid-tier", "Below Mid-tier"))) -> Mid-tier
A7: Rookie Scale | B7: =COUNTIF('Filtered Data'!D:D, A7) -> 48 | D7: Isabelle Harrison | E7: Veteran Minimum | F7: 17.3 | G7: =IF(F7>=25, "Super Max", IF(F7>=20, "Standard Max", IF(F7>=13, "Mid-tier", "Below Mid-tier"))) -> Mid-tier
A8: Special / Short-term | B8: =COUNTIF('Filtered Data'!D:D, A8) -> 44 | D8: Jessica Shepard | E8: Special / Short-term | F8: 20.9 | G8: =IF(F8>=25, "Super Max", IF(F8>=20, "Standard Max", IF(F8>=13, "Mid-tier", "Below Mid-tier"))) -> Standard Max
D9: Kennedy Burke | E9: Veteran Minimum | F9: 13.9 | G9: =IF(F9>=25, "Super Max", IF(F9>=20, "Standard Max", IF(F9>=13, "Mid-tier", "Below Mid-tier"))) -> Mid-tier
A10: Player pay status | D10: Kiki Iriafen | E10: Rookie Scale | F10: 17.3 | G10: =IF(F10>=25, "Super Max", IF(F10>=20, "Standard Max", IF(F10>=13, "Mid-tier", "Below Mid-tier"))) -> Mid-tier
A11: Status | B11: Total | D11: Paige Bueckers | E11: Rookie Scale | F11: 21.9 | G11: =IF(F11>=25, "Super Max", IF(F11>=20, "Standard Max", IF(F11>=13, "Mid-tier", "Below Mid-tier"))) -> Standard Max
A12: Underpaid | B12: {=SUMPRODUCT(('Filtered Data'!B2:B183<80336) * ('Filtered Data'!H2:H183>=13))} -> 35 | D12: Sonia Citron | E12: Rookie Scale | F12: 16.4 | G12: =IF(F12>=25, "Super Max", IF(F12>=20, "Standard Max", IF(F12>=13, "Mid-tier", "Below Mid-tier"))) -> Mid-tier
A13: Overpaid | B13: {=SUMPRODUCT(('Filtered Data'!B2:B183>=80336) * ('Filtered Data'!H2:H183<13))} -> 34 | D13: Caitlin Clark | E13: Rookie Scale | F13: 16.6 | G13: =IF(F13>=25, "Super Max", IF(F13>=20, "Standard Max", IF(F13>=13, "Mid-tier", "Below Mid-tier"))) -> Mid-tier
A14: High Pay / High PER | B14: {=SUMPRODUCT(('Filtered Data'!B2:B183>=80336) * ('Filtered Data'!H2:H183>=13))} -> 57 | D14: Cameron Brink | E14: Rookie Scale | F14: 15.2 | G14: =IF(F14>=25, "Super Max", IF(F14>=20, "Standard Max", IF(F14>=13, "Mid-tier", "Below Mid-tier"))) -> Mid-tier
A15: Low Pay / Low PER | B15: {=SUMPRODUCT(('Filtered Data'!B2:B183<80336) * ('Filtered Data'!H2:H183<13))} -> 56 | D15: Kamilla Cardoso | E15: Rookie Scale | F15: 19.6 | G15: =IF(F15>=25, "Super Max", IF(F15>=20, "Standard Max", IF(F15>=13, "Mid-tier", "Below Mid-tier"))) -> Mid-tier
D16: Emma Meesseman | E16: Veteran Minimum | F16: 23.6 | G16: =IF(F16>=25, "Super Max", IF(F16>=20, "Standard Max", IF(F16>=13, "Mid-tier", "Below Mid-tier"))) -> Standard Max
D17: Aneesah Morrow | E17: Rookie Scale | F17: 14.9 | G17: =IF(F17>=25, "Super Max", IF(F17>=20, "Standard Max", IF(F17>=13, "Mid-tier", "Below Mid-tier"))) -> Mid-tier
D18: Saniya Rivers | E18: Rookie Scale | F18: 13.6 | G18: =IF(F18>=25, "Super Max", IF(F18>=20, "Standard Max", IF(F18>=13, "Mid-tier", "Below Mid-tier"))) -> Mid-tier
D19: Aaliyah Edwards | E19: Rookie Scale | F19: 13 | G19: =IF(F19>=25, "Super Max", IF(F19>=20, "Standard Max", IF(F19>=13, "Mid-tier", "Below Mid-tier"))) -> Mid-tier
D20: Angel Reese | E20: Rookie Scale | F20: 19.6 | G20: =IF(F20>=25, "Super Max", IF(F20>=20, "Standard Max", IF(F20>=13, "Mid-tier", "Below Mid-tier"))) -> Mid-tier
D21: Leila Lacan | E21: Rookie Scale | F21: 15.8 | G21: =IF(F21>=25, "Super Max", IF(F21>=20, "Standard Max", IF(F21>=13, "Mid-tier", "Below Mid-tier"))) -> Mid-tier
D22: Anastasiia Olairi Kosu | E22: Rookie Scale | F22: 13.9 | G22: =IF(F22>=25, "Super Max", IF(F22>=20, "Standard Max", IF(F22>=13, "Mid-tier", "Below Mid-tier"))) -> Mid-tier
D23: Makayla Timpson | E23: Rookie Scale | F23: 17.5 | G23: =IF(F23>=25, "Super Max", IF(F23>=20, "Standard Max", IF(F23>=13, "Mid-tier", "Below Mid-tier"))) -> Mid-tier
D24: Te-Hina Paopao | E24: Rookie Scale | F24: 13.2 | G24: =IF(F24>=25, "Super Max", IF(F24>=20, "Standard Max", IF(F24>=13, "Mid-tier", "Below Mid-tier"))) -> Mid-tier
D25: JJ Quinerly | E25: Rookie Scale | F25: 13.1 | G25: =IF(F25>=25, "Super Max", IF(F25>=20, "Standard Max", IF(F25>=13, "Mid-tier", "Below Mid-tier"))) -> Mid-tier
D26: Li Yueru | E26: Veteran Minimum | F26: 13.4 | G26: =IF(F26>=25, "Super Max", IF(F26>=20, "Standard Max", IF(F26>=13, "Mid-tier", "Below Mid-tier"))) -> Mid-tier
D27: Aari McDonald | E27: Special / Short-term | F27: 14.1 | G27: =IF(F27>=25, "Super Max", IF(F27>=20, "Standard Max", IF(F27>=13, "Mid-tier", "Below Mid-tier"))) -> Mid-tier
... D37: Amy Okonkwo | E37: Special / Short-term | F37: 21.9 | G37: =IF(F37>=25, "Super Max", IF(F37>=20, "Standard Max", IF(F37>=13, "Mid-tier", "Below Mid-tier"))) -> Standard Max

Sheet Full data
A1: Player | B1: 2025 Salary | C1: Years in the league | D1: 2025 Status | E1: 2025 Signing | F1: G | G1: MIN | H1: PER | I1: PER*Min | J1: WS | K1: Off WS | L1: Def WS | M1: WS/40 | N1: Off WS/40 | O1: Def WS/40 | P1: Player Off Rtg | Q1: Player Def Rtg
A2: A'ja Wilson | B2: 200000 | C2: 8 | D2: Mid-tier Veteran | E2: RFA | F2: 40 | G2: 1247 | H2: 33.1 | I2: 41343 | J2: 8.9 | K2: 6.3 | L2: 2.6 | M2: 0.29 | N2: 0.2 | O2: 0.08 | P2: 118.6 | Q2: 93.3
A3: Aaliyah Edwards | B3: 74909 | C3: 2 | D3: Rookie Scale | E3: Rookie | F3: 36 | G3: 534 | H3: 13 | I3: 6951 | J3: 0.9 | K3: 0.2 | L3: 0.7 | M3: 0.07 | N3: 0.02 | O3: 0.05 | P3: 95.7 | Q3: 100.4
A4: Aaliyah Nye | B4: 69267 | C4: 2 | D4: Rookie Scale | E4: Rookie | F4: 44 | G4: 671 | H4: 5.8 | I4: 3909 | J4: 0.3 | K4: -0.1 | L4: 0.3 | M4: 0.02 | N4: 0 | O4: 0.02 | P4: 90.9 | Q4: 106.2
A5: Aari McDonald | B5: 52333 | C5: 5 | D5: Special / Short-term | E5: UFA | F5: 20 | G5: 525 | H5: 14.1 | I5: 7383 | J5: 1.4 | K5: 0.9 | L5: 0.5 | M5: 0.11 | N5: 0.07 | O5: 0.04 | P5: 105.8 | Q5: 102.8
A6: Aari McDonald | B6: 6459 | C6: 5 | D6: Special / Short-term | E6: Hardship | F6: 20 | G6: 525 | H6: 14.1 | I6: 7383 | J6: 1.4 | K6: 0.9 | L6: 0.5 | M6: 0.11 | N6: 0.07 | O6: 0.04 | P6: 105.8 | Q6: 102.8
A7: Aerial Powers | B7: 11924 | C7: 10 | D7: Special / Short-term | E7: UFA | F7: 10 | G7: 167 | H7: 16.4 | I7: 2736 | J7: 0.6 | K7: 0.3 | L7: 0.3 | M7: 0.15 | N7: 0.07 | O7: 0.08 | P7: 104.7 | Q7: 94.6
A8: Aerial Powers | B8: 9274 | C8: 10 | D8: Special / Short-term | E8: Hardship | F8: 10 | G8: 167 | H8: 16.4 | I8: 2736 | J8: 0.6 | K8: 0.3 | L8: 0.3 | M8: 0.15 | N8: 0.07 | O8: 0.08 | P8: 104.7 | Q8: 94.6
A9: Aerial Powers | B9: 3975 | C9: 10 | D9: Special / Short-term | E9: Hardship | F9: 10 | G9: 167 | H9: 16.4 | I9: 2736 | J9: 0.6 | K9: 0.3 | L9: 0.3 | M9: 0.15 | N9: 0.07 | O9: 0.08 | P9: 104.7 | Q9: 94.6
A10: Aerial Powers | C10: 10 | E10: UFA | F10: 10 | G10: 167 | H10: 16.4 | I10: 2736 | J10: 0.6 | K10: 0.3 | L10: 0.3 | M10: 0.15 | N10: 0.07 | O10: 0.08 | P10: 104.7 | Q10: 94.6
A11: Ajae Petty | B11: 2915 | C11: 2 | D11: Special / Short-term | E11: Hardship | F11: 2 | G11: 6000 | H11: -0.9 | I11: -5 | J11: 0 | K11: 0 | L11: 0 | M11: 0.01 | N11: 0 | O11: 0.01 | Q11: 107.5
A12: Ajae Petty | B12: 1250 | C12: 2 | D12: Special / Short-term | E12: Hardship | F12: 2 | G12: 6000 | H12: -0.9 | I12: -5 | J12: 0 | K12: 0 | L12: 0 | M12: 0.01 | N12: 0 | O12: 0.01 | Q12: 107.5
A13: Alanna Smith | B13: 150000 | C13: 7 | D13: Mid-tier Veteran | E13: UFA | F13: 42 | G13: 1114 | H13: 18 | I13: 20095 | J13: 4.5 | K13: 2.2 | L13: 2.3 | M13: 0.16 | N13: 0.08 | O13: 0.08 | P13: 110 | Q13: 93.7
A14: Alexis Prince | B14: 3975 | C14: 1 | D14: Special / Short-term | E14: UFA | F14: 1 | G14: 22 | H14: -1.4 | I14: -30 | J14: 0 | K14: -0.1 | L14: 0.1 | M14: 0 | N14: -0.17 | O14: 0.17 | P14: 40.5 | Q14: 76.1
A15: Alissa Pili | B15: 37769 | C15: 3 | D15: Special / Short-term | E15: -- | F15: 19 | G15: 99 | H15: 12.5 | I15: 1232 | J15: 0.2 | K15: 0.2 | L15: 0.1 | M15: 0.1 | N15: 0.07 | O15: 0.03 | P15: 106.3 | Q15: 103.2
A16: Alissa Pili | B16: 11661 | C16: 3 | D16: Special / Short-term | E16: UFA | F16: 19 | G16: 99 | H16: 12.5 | I16: 1232 | J16: 0.2 | K16: 0.2 | L16: 0.1 | M16: 0.1 | N16: 0.07 | O16: 0.03 | P16: 106.3 | Q16: 103.2
A17: Alissa Pili | B17: 10550 | C17: 3 | D17: Special / Short-term | E17: UFA | F17: 19 | G17: 99 | H17: 12.5 | I17: 1232 | J17: 0.2 | K17: 0.2 | L17: 0.1 | M17: 0.1 | N17: 0.07 | O17: 0.03 | P17: 106.3 | Q17: 103.2
A18: Aliyah Boston | B18: 83371 | C18: 3 | D18: Rookie Scale | E18: Rookie | F18: 44 | G18: 1327 | H18: 22.5 | I18: 29890 | J18: 6.7 | K18: 4.7 | L18: 2 | M18: 0.2 | N18: 0.14 | O18: 0.06 | P18: 117.9 | Q18: 98.1
A19: Allisha Gray | B19: 190000 | C19: 9 | D19: Mid-tier Veteran | E19: RFA | F19: 42 | G19: 1451 | H19: 19.6 | I19: 28457 | J19: 7.2 | K19: 5.2 | L19: 2 | M19: 0.2 | N19: 0.14 | O19: 0.06 | P19: 119 | Q19: 99.2
A20: Alysha Clark | B20: 205908 | C20: 16 | D20: Mid-tier Veteran | E20: UFA | F20: 42 | G20: 828 | H20: 7.1 | I20: 5868 | J20: 1 | K20: 0.3 | L20: 0.8 | M20: 0.05 | N20: 0.01 | O20: 0.04 | P20: 97.3 | Q20: 102.9
A21: Alyssa Thomas | B21: 215000 | C21: 12 | D21: Standard Max | E21: Core | F21: 39 | G21: 1221 | H21: 25.1 | I21: 30588 | J21: 6.6 | K21: 4.4 | L21: 2.2 | M21: 0.22 | N21: 0.14 | O21: 0.07 | P21: 113.5 | Q21: 95.7
A22: Amy Okonkwo | B22: 7774 | C22: 3 | D22: Special / Short-term | E22: UFA | F22: 8 | G22: 157 | H22: 21.9 | I22: 3429 | J22: 0.5 | K22: 0.5 | L22: 0 | M22: 0.14 | N22: 0.14 | O22: 0 | P22: 120.6 | Q22: 110.1
A23: Amy Okonkwo | B23: 2915 | C23: 3 | D23: Special / Short-term | E23: UFA | F23: 8 | G23: 157 | H23: 21.9 | I23: 3429 | J23: 0.5 | K23: 0.5 | L23: 0 | M23: 0.14 | N23: 0.14 | O23: 0 | P23: 120.6 | Q23: 110.1
A24: Anastasiia Olairi Kosu | B24: 69267 | C24: 2 | D24: Rookie Scale | E24: Rookie | F24: 21 | G24: 80 | H24: 13.9 | I24: 1105 | J24: 0.2 | K24: 0.1 | L24: 0.1 | M24: 0.08 | N24: 0.04 | O24: 0.04 | P24: 98.7 | Q24: 101.6
... A73: Gabby Williams | B73: 225000 | C73: 8 | D73: Standard Max | E73: Core | F73: 44 | G73: 1391 | H73: 15.6 | I73: 21728 | J73: 3.5 | K73: 1.3 | L73: 2.2 | M73: 0.1 | N73: 0.04 | O73: 0.06 | P73: 99.6 | Q73: 97.3
A74: Georgia Amoore | B74: 75643 | C74: 1 | D74: Rookie Scale | E74: Rookie | F74: 0 | G74: 0 | K74: 0
A75: Grace Berger | B75: 17214 | C75: 3 | D75: Special / Short-term | E75: UFA | F75: 19 | G75: 418 | H75: 6 | I75: 2527 | J75: -0.3 | K75: -0.3 | L75: 0 | M75: -0.03 | N75: -0.03 | O75: 0 | P75: 82.1 | Q75: 110.3
A76: Grace Berger | B76: 11661 | C76: 3 | D76: Special / Short-term | E76: Hardship | F76: 19 | G76: 418 | H76: 6 | I76: 2527 | J76: -0.3 | K76: -0.3 | L76: 0 | M76: -0.03 | N76: -0.03 | O76: 0 | P76: 82.1 | Q76: 110.3
A77: Grace Berger | B77: 1666 | C77: 3 | D77: Special / Short-term | E77: Hardship | F77: 19 | G77: 418 | H77: 6 | I77: 2527 | J77: -0.3 | K77: -0.3 | L77: 0 | M77: -0.03 | N77: -0.03 | O77: 0 | P77: 82.1 | Q77: 110.3
A78: Hailey Van Lith | B78: 72455 | C78: 2 | D78: Rookie Scale | E78: Rookie | F78: 29 | G78: 361 | H78: 5.8 | I78: 2085 | J78: -0.5 | K78: -0.5 | L78: 0 | M78: -0.06 | N78: -0.06 | O78: 0 | P78: 80.3 | Q78: 110.4
A79: Haley Jones | B79: 36094 | C79: 4 | D79: Special / Short-term | E79: UFA | F79: 28 | G79: 594 | H79: 11.4 | I79: 6789 | J79: 0.4 | K79: 0 | L79: 0.3 | M79: 0.03 | N79: 0 | O79: 0.02 | P79: 92.6 | Q79: 105.6
A80: Haley Jones | B80: 5553 | C80: 4 | D80: Special / Short-term | E80: Hardship | F80: 28 | G80: 594 | H80: 11.4 | I80: 6789 | J80: 0.4 | K80: 0 | L80: 0.3 | M80: 0.03 | N80: 0 | O80: 0.02 | P80: 92.6 | Q80: 105.6
A81: Haley Jones | B81: 4998 | C81: 4 | D81: Special / Short-term | E81: Hardship | F81: 28 | G81: 594 | H81: 11.4 | I81: 6789 | J81: 0.4 | K81: 0 | L81: 0.3 | M81: 0.03 | N81: 0 | O81: 0.02 | P81: 92.6 | Q81: 105.6
A82: Haley Peters | B82: 39747 | C82: 9 | D82: Special / Short-term | E82: UFA | F82: 33 | G82: 380 | H82: 5 | I82: 1894 | J82: -0.3 | K82: -0.3 | L82: 0 | M82: -0.03 | N82: -0.03 | O82: 0 | P82: 82.4 | Q82: 109.3
A83: Haley Peters | B83: 25173 | C83: 9 | D83: Special / Short-term | E83: UFA | F83: 33 | G83: 380 | H83: 5 | I83: 1894 | J83: -0.3 | K83: -0.3 | L83: 0 | M83: -0.03 | N83: -0.03 | O83: 0 | P83: 82.4 | Q83: 109.3
A84: Haley Peters | B84: 13911 | C84: 9 | D84: Special / Short-term | E84: UFA | F84: 33 | G84: 380 | H84: 5 | I84: 1894 | J84: -0.3 | K84: -0.3 | L84: 0 | M84: -0.03 | N84: -0.03 | O84: 0 | P84: 82.4 | Q84: 109.3
A85: Iliana Rupert | B85: 32207 | C85: 4 | D85: Rookie Scale | E85: Rookie | F85: 21 | G85: 486 | H85: 16.2 | I85: 7892 | J85: 1.8 | K85: 1.2 | L85: 0.6 | M85: 0.15 | N85: 0.1 | O85: 0.05 | P85: 116.6 | Q85: 100.6
A86: Isabelle Harrison | B86: 78831 | C86: 11 | D86: Veteran Minimum | E86: UFA | F86: 34 | G86: 360 | H86: 17.3 | I86: 6240 | J86: 1.2 | K86: 0.7 | L86: 0.5 | M86: 0.13 | N86: 0.08 | O86: 0.06 | P86: 105.9 | Q86: 98.5
... A108: Kalani Brown | B108: 128750 | C108: 7 | D108: Mid-tier Veteran | E108: UFA | F108: 29 | G108: 370 | H108: 18.6 | I108: 6903 | J108: 1.6 | K108: 1 | L108: 0.6 | M108: 0.17 | N108: 0.11 | O108: 0.06 | P108: 119 | Q108: 97.5
A109: Kamiah Smalls | B109: 7774 | C109: 1 | D109: Special / Short-term | E109: UFA | F109: 3 | G109: 3000 | H109: 0 | I109: 0 | J109: 0 | K109: 0 | L109: 0 | M109: 0.05 | N109: 0 | O109: 0.05 | Q109: 100.7
...

Sheet Cleaned Data
A1: Player | B1: 2025 Salary | C1: 2025 Signing | D1: G | E1: MIN | F1: PER | G1: PER*Min | H1: WS | I1: Off WS | J1: Def WS | K1: WS/40 | L1: Off WS/40 | M1: Def WS/40 | N1: Player Off Rtg | O1: Player Def Rtg
A2: Kelsey Mitchell | B2: 269244 | C2: Core | D2: 44 | E2: 1381 | F2: 20 | G2: 27655 | H2: 5.6 | I2: 4.8 | J2: 0.8 | K2: 0.16 | L2: 0.14 | M2: 0.02 | N2: 114 | O2: 105.4
A3: Arike Ogunbowale | B3: 249032 | C3: -- | D3: 29 | E3: 966 | F3: 13.3 | G3: 12825 | H3: 1.3 | I3: 1.3 | J3: 0 | K3: 0.05 | L3: 0.05 | M3: 0 | N3: 101.8 | O3: 110
A4: Jewell Loyd | B4: 249032 | C4: Core | D4: 44 | E4: 1245 | F4: 13.4 | G4: 16739 | H4: 2.9 | I4: 2 | J4: 1 | K4: 0.09 | L4: 0.06 | M4: 0.03 | N4: 106.5 | O4: 104
A5: Kahleah Copper | B5: 248134 | C5: Core | D5: 28 | E5: 752 | F5: 14.7 | G5: 11094 | H5: 1.5 | I5: 0.8 | J5: 0.8 | K5: 0.08 | L5: 0.04 | M5: 0.04 | N5: 98.4 | O5: 101.8
A6: Gabby Williams | B6: 225000 | C6: Core | D6: 44 | E6: 1391 | F6: 15.6 | G6: 21728 | H6: 3.5 | I6: 1.3 | J6: 2.2 | K6: 0.1 | L6: 0.04 | M6: 0.06 | N6: 99.6 | O6: 97.3
A7: Ariel Atkins | B7: 223000 | C7: -- | D7: 34 | E7: 970 | F7: 16 | G7: 15499 | H7: 2 | I7: 1.5 | J7: 0.4 | K7: 0.08 | L7: 0.06 | M7: 0.02 | N7: 103.6 | O7: 106.5
A8: Breanna Stewart | B8: 222400 | C8: Core | D8: 31 | E8: 948 | F8: 23.7 | G8: 22486 | H8: 4.7 | I8: 3.2 | J8: 1.5 | K8: 0.2 | L8: 0.13 | M8: 0.07 | N8: 112.6 | O8: 97.3
A9: Sabrina Ionescu | B9: 222060 | C9: Rookie | D9: 38 | E9: 1194 | F9: 20.6 | G9: 24600 | H9: 4.5 | I9: 3.2 | J9: 1.3 | K9: 0.15 | L9: 0.11 | M9: 0.04 | N9: 107 | O9: 101.3
A10: Satou Sabally | B10: 215000 | C10: Core | D10: 39 | E10: 1039 | F10: 19.6 | G10: 20393 | H10: 4 | I10: 2.4 | J10: 1.6 | K10: 0.15 | L10: 0.09 | M10: 0.06 | N10: 105.5 | O10: 98.1
A11: Alyssa Thomas | B11: 215000 | C11: Core | D11: 39 | E11: 1221 | F11: 25.1 | G11: 30588 | H11: 6.6 | I11: 4.4 | J11: 2.2 | K11: 0.22 | L11: 0.14 | M11: 0.07 | N11: 113.5 | O11: 95.7
A12: Brittney Griner | B12: 214466 | C12: UFA | D12: 39 | E12: 810 | F12: 16.2 | G12: 13154 | H12: 2.4 | I12: 1.1 | J12: 1.4 | K12: 0.12 | L12: 0.05 | M12: 0.07 | N12: 102.1 | O12: 96.6
A13: Natasha Howard | B13: 214466 | C13: UFA | D13: 44 | E13: 1060 | F13: 19.1 | G13: 20269 | H13: 4.1 | I13: 2.4 | J13: 1.7 | K13: 0.15 | L13: 0.09 | M13: 0.06 | N13: 109.3 | O13: 97.4
... A67: Lexie Brown | B67: 96408 | C67: UFA | D67: 24 | E67: 227 | F67: 8.5 | G67: 1929 | H67: 0.4 | I67: 0.2 | J67: 0.2 | K67: 0.07 | L67: 0.03 | M67: 0.04 | N67: 103.1 | O67: 103
A68: Katie Lou Samuelson | B68: 95835 | C68: UFA | D68: 0 | E68: 0 | I68: 0
A69: Rachel Banham | B69: 95000 | C69: UFA | D69: 44 | E69: 1081 | F69: 10.6 | G69: 11458 | H69: 1 | I69: 1.3 | J69: -0.2 | K69: 0.04 | L69: 0.05 | M69: -0.01 | N69: 103.1 | O69: 111.8
A70: Sug Sutton | B70: 93831 | C70: Reserved | D70: 43 | E70: 1122 | F70: 9.8 | G70: 11051 | H70: 1.1 | I70: 0.5 | J70: 0.6 | K70: 0.04 | L70: 0.02 | M70: 0.02 | N70: 96.5 | O70: 106.1
A71: Shakira Austin | B71: 91981 | C71: Rookie | D71: 38 | E71: 874 | F71: 18.5 | G71: 16164 | H71: 1.6 | I71: 0.2 | J71: 1.5 | K71: 0.07 | L71: 0.01 | M71: 0.07 | N71: 92.9 | O71: 96.8
A72: NaLyssa Smith | B72: 91981 | C72: Rookie | D72: 45 | E72: 956 | F72: 13.2 | G72: 12601 | H72: 2.3 | I72: 1.3 | J72: 0.9 | K72: 0.09 | L72: 0.06 | M72: 0.04 | N72: 105.6 | O72: 102.4
A73: Rhyne Howard | B73: 91981 | C73: Rookie | D73: 33 | E73: 1151 | F73: 18.2 | G73: 20907 | H73: 4.9 | I73: 3.1 | J73: 1.8 | K73: 0.17 | L73: 0.11 | M73: 0.06 | N73: 111 | O73: 97.6
A74: Katie Lou Samuelson | B74: 90000 | C74: UFA | D74: 0 | E74: 0 | I74: 0
A75: Lindsay Allen | B75: 90000 | C75: UFA | D75: 31 | E75: 450 | F75: 6.6 | G75: 2960 | H75: -0.1 | I75: 0 | J75: -0.1 | K75: -0.01 | L75: 0 | M75: -0.01 | N75: 92.7 | O75: 112.6
A76: Sydney Colson | B76: 90000 | C76: UFA | D76: 30 | E76: 404 | F76: 5.9 | G76: 2365 | H76: 0.1 | I76: -0.2 | J76: 0.3 | K76: 0.01 | L76: -0.02 | M76: 0.03 | N76: 86.5 | O76: 103.8
A77: Temi Fágbénlé | B77: 90000 | C77: Reserved | D77: 39 | E77: 925 | F77: 12.8 | G77: 11845 | H77: 2.4 | I77: 1 | J77: 1.3 | K77: 0.1 | L77: 0.04 | M77: 0.06 | N77: 102.9 | O77: 98.5
A78: Dana Evans | B78: 89000 | C78: RFA | D78: 44 | E78: 777 | F78: 11 | G78: 8551 | H78: 1.1 | I78: 0.9 | J78: 0.3 | K78: 0.06 | L78: 0.04 | M78: 0.01 | N78: 101.2 | O78: 107.2
A79: Lexie Hull | B79: 88261 | C79: Rookie | D79: 44 | E79: 1189 | F79: 10.4 | G79: 12374 | H79: 2.7 | I79: 1.4 | J79: 1.2 | K79: 0.09 | L79: 0.05 | M79: 0.04 | N79: 106.4 | O79: 101.7
A80: Yvonne Anderson | B80: 85000 | C80: UFA | D80: 1 | E80: 12 | F80: 1.1 | G80: 13000 | H80: 0 | I80: 0 | J80: 0 | K80: 0.01 | L80: -0.11 | M80: 0.12 | N80: 50.2 | O80: 86.5
A81: Brianna Turner | B81: 85000 | C81: UFA | D81: 27 | E81: 233 | F81: 7.4 | G81: 1721 | H81: 0.3 | I81: 0.1 | J81: 0.2 | K81: 0.06 | L81: 0.02 | M81: 0.04 | N81: 100.3 | O81: 102.9
A82: Julie Allemand | B82: 85000 | C82: SuspCE | D82: 34 | E82: 963 | F82: 11.4 | G82: 10962 | H82: 1.6 | I82: 1.3 | J82: 0.3 | K82: 0.07 | L82: 0.05 | M82: 0.01 | N82: 110.3 | O82: 107.8
A83: Kierstan Bell | B83: 84543 | C83: Rookie | D83: 35 | E83: 427 | F83: 10.5 | G83: 4487 | H83: 0.5 | I83: 0.1 | J83: 0.4 | K83: 0.05 | L83: 0.01 | M83: 0.03 | N83: 94.9 | O83: 103.3
A84: Maddy Siegrist | B84: 83371 | C84: Rookie | D84: 26 | E84: 702 | F84: 17.2 | G84: 12107 | H84: 1.9 | I84: 1.9 | J84: 0 | K84: 0.11 | L84: 0.11 | M84: 0 | N84: 116.9 | O84: 110.1
A85: Aliyah Boston | B85: 83371 | C85: Rookie | D85: 44 | E85: 1327 | F85: 22.5 | G85: 29890 | H85: 6.7 | I85: 4.7 | J85: 2 | K85: 0.2 | L85: 0.14 | M85: 0.06 | N85: 117.9 | O85: 98.1
A86: Diamond Miller | B86: 83371 | C86: -- | D86: 40 | E86: 434 | F86: 8.5 | G86: 3694 | H86: 0.5 | I86: 0.1 | J86: 0.4 | K86: 0.04 | L86: 0.01 | M86: 0.03 | N86: 94.4 | O86: 103.5
... A107: Emma Meesseman | B107: 75694 | C107: UFA | D107: 17 | E107: 440 | F107: 23.6 | G107: 10358 | H107: 2 | I107: 1.4 | J107: 0.6 | K107: 0.18 | L107: 0.13 | M107: 0.05 | N107: 115.1 | O107: 99.9
A108: Georgia Amoore | B108: 75643 | C108: Rookie | D108: 0 | E108: 0 | I108: 0
A109: Aneesah Morrow | B109: 75643 | C109: Rookie | D109: 41 | E109: 775 | F109: 14.9 | G109: 11528 | H109: 1 | I109: 0.3 | J109: 0.7 | K109: 0.05 | L109: 0.02 | M109: 0.04 | N109: 94.9 | O109: 103
A110: Saniya Rivers | B110: 75643 | C110: Rookie | D110: 42 | E110: 1097 | F110: 13.6 | G110: 14902 | H110: 1.2 | I110: 0.7 | J110: 0.5 | K110: 0.04 | L110: 0.02 | M110: 0.02 | N110: 97.6 | O110: 106.6
A111: Aaliyah Edwards | B111: 74909 | C111: Rookie | D111: 36 | E111: 534 | F111: 13 | G111: 6951 | H111: 0.9 | I111: 0.2 | J111: 0.7 | K111: 0.07 | L111: 0.02 | M111: 0.05 | N111: 95.7 | O111: 100.4
A112: Jacy Sheldon | B112: 74909 | C112: Rookie | D112: 30 | E112: 708 | F112: 11.8 | G112: 8376 | H112: 1 | I112: 1.1 | J112: -0.1 | K112: 0.06 | L112: 0.06 | M112: 0 | N112: 110.2 | O112: 110.9
A113: Angel Reese | B113: 74909 | C113: Rookie | D113: 30 | E113: 947 | F113: 19.6 | G113: 18533 | H113: 2.3 | I113: 1.3 | J113: 1 | K113: 0.1 | L113: 0.06 | M113: 0.04 | N113: 100.6 | O113: 101.9
...
