Workbook

Sheet Salary Cap
A1: Season | B1: Cap | C1: Adjusted Cap | D1: Cap Increase | E1: Minimum salary | F1: Maximum salary | G1: Max increase | H1: Min % of cap | I1: Max % of cap | J1: Average Salary (Filtered) | K1: Average Salary | L1: Min Salary | M1: Max Salary | N1: Adjusted Average Salary | O1: Adjusted Min Salary | P1: Adjusted Max Salary
A2: 2003 | B2: 622000 | E2: 30000 | F2: 85000 | H2: 4.8% | I2: 13.7%
A3: 2004 | B3: 647000 | D3: 4.0% | E3: 30600 | F3: 87000 | G3: 2.4% | H3: 4.7% | I3: 13.4%
A4: 2005 | B4: 673000 | D4: 4.0% | E4: 31200 | F4: 89000 | G4: 2.3% | H4: 4.6% | I4: 13.2%
A5: 2006 | B5: 700000 | D5: 4.0% | E5: 31800 | F5: 91000 | G5: 2.2% | H5: 4.5% | I5: 13.0%
A6: 2007 | B6: 728000 | D6: 4.0% | E6: 32400 | F6: 93000 | G6: 2.2% | H6: 4.5% | I6: 12.8%
A7: 2008 | B7: 772000 | D7: 6.0% | E7: 34500 | F7: 97500 | G7: 4.8% | H7: 4.5% | I7: 12.6%
A8: 2009 | B8: 803000 | D8: 4.0% | E8: 35190 | F8: 99500 | G8: 2.1% | H8: 4.4% | I8: 12.4%
A9: 2010 | B9: 827000 | D9: 3.0% | E9: 35880 | F9: 101500 | G9: 2.0% | H9: 4.3% | I9: 12.3%
A10: 2011 | B10: 852000 | D10: 3.0% | E10: 36750 | F10: 103500 | G10: 2.0% | H10: 4.3% | I10: 12.1%
A11: 2012 | B11: 878000 | D11: 3.1% | E11: 37260 | F11: 105500 | G11: 1.9% | H11: 4.2% | I11: 12.0%
A12: 2013 | B12: 913000 | D12: 4.0% | E12: 37950 | F12: 107500 | G12: 1.9% | H12: 4.2% | I12: 11.8%
A13: 2014 | B13: 901000 | D13: -1.3% | E13: 38150 | F13: 107500 | G13: 0.0% | H13: 4.2% | I13: 11.9%
A14: 2015 | B14: 919300 | D14: 2.0% | E14: 38913 | F14: 109500 | G14: 1.9% | H14: 4.2% | I14: 11.9%
... A17: 2018 | B17: 976300 | D17: 2.0% | E17: 41202 | F17: 115500 | G17: 1.8% | H17: 4.2% | I17: 11.8%
A18: 2019 | B18: 996100 | C18: =2.2*B18 -> 2191420 | D18: 2.0% | E18: 41965 | F18: 117500 | G18: 1.7% | H18: 4.2% | I18: 11.8% | J18: =ROUND(AVERAGE('2019'!B2:B150),2) -> 77357.07 | K18: =ROUND(AVERAGE('2019'!B:B),2) -> 74905.82 | L18: =ROUND(MIN('2019'!B:B),2) -> 2723 | M18: =ROUND(MAX('2019'!B:B),2) -> 127500 | N18: =K18/0.186 -> 402719.46 | O18: =L18/0.186 -> 14639.785 | P18: =M18/0.186 -> 685483.87
A19: 2020 | B19: 1300000 | C19: =2.2*B19 -> 2860000 | D19: 30.5% | E19: 57000 | F19: 215000 | G19: 83.0% | H19: 4.4% | I19: 16.5% | J19: =ROUND(AVERAGE('2020'!C2:C163),2) -> 94367.5 | K19: =ROUND(AVERAGE('2020'!C:C),2) -> 90791.5 | L19: =ROUND(MIN('2020'!C:C),2) -> 4560 | M19: =ROUND(MAX('2020'!C:C),2) -> 215000 | N19: =K19/0.186 -> 488126.34 | O19: =L19/0.186 -> 24516.129 | P19: =M19/0.186 -> 1155914
A20: 2021 | B20: 1339000 | C20: =2.2*B20 -> 2945800 | D20: 3.0% | E20: 58710 | F20: 221450 | G20: 3.0% | H20: 4.4% | I20: 16.5% | J20: =ROUND(AVERAGE('2021'!B2:B135),2) -> 113064.63 | K20: =ROUND(AVERAGE('2021'!B:B),2) -> 99166.57 | L20: =ROUND(MIN('2021'!B:B),2) -> 1391 | M20: =ROUND(MAX('2021'!B:B),2) -> 221450 | N20: =K20/0.186 -> 533153.6 | O20: =L20/0.186 -> 7478.4946 | P20: =M20/0.186 -> 1190591.4
A21: 2022 | B21: 1379200 | C21: =2.2*B21 -> 3034240 | D21: 3.0% | E21: 60471 | F21: 228094 | G21: 3.0% | H21: 4.4% | I21: 16.5% | J21: =ROUND(AVERAGE('2022'!B2:B132),2) -> 119519.47 | K21: =ROUND(AVERAGE('2022'!B:N),2) -> 97813.72 | L21: =ROUND(MIN('2022'!B:N),2) -> 2245 | M21: =ROUND(MAX('2022'!B:N),2) -> 228094 | N21: =K21/0.186 -> 525880.22 | O21: =L21/0.186 -> 12069.892 | P21: =M21/0.186 -> 1226311.8
A22: 2023 | B22: 1420500 | C22: =2.2*B22 -> 3125100 | D22: 3.0% | E22: 62285 | F22: 234936 | G22: 3.0% | H22: 4.4% | I22: 16.5% | J22: =ROUND(AVERAGE('2023'!C2:C135),2) -> 122058.69 | K22: =ROUND(AVERAGE('2023'!C:C),2) -> 115425.65 | L22: =ROUND(MIN('2023'!C:C),2) -> 1625 | M22: =ROUND(MAX('2023'!C:C),2) -> 242154 | N22: =K22/0.186 -> 620568.01 | O22: =L22/0.186 -> 8736.5591 | P22: =M22/0.186 -> 1301903.2
A23: 2024 | B23: 1463200 | C23: =2.2*B23 -> 3219040 | D23: 3.0% | E23: 64154 | F23: 241984 | G23: 3.0% | H23: 4.4% | I23: 16.5% | J23: =ROUND(AVERAGE('2024'!C7:C130),2) -> 121666.57 | K23: =ROUND(AVERAGE('2024'!C:C),2) -> 114452.64 | L23: =ROUND(MIN('2024'!C:C),2) -> 635 | M23: =ROUND(MAX('2024'!C:C),2) -> 241984 | N23: =K23/0.186 -> 615336.77 | O23: =L23/0.186 -> 3413.9785 | P23: =M23/0.186 -> 1300989.2
A24: 2025 | B24: 1507100 | C24: =2.2*B24 -> 3315620 | D24: 3.0% | E24: 66079 | F24: 249244 | G24: 3.0% | H24: 4.4% | I24: 16.5% | J24: =ROUND(AVERAGE('2025'!C2:C134),2) -> 121930.49 | K24: =ROUND(AVERAGE('2025'!C:C),2) -> 103772.6 | L24: =ROUND(MIN('2025'!C:C),2) -> 833 | M24: =ROUND(MAX('2025'!C:C),2) -> 269244 | N24: =K24/0.186 -> 557917.2 | O24: =L24/0.186 -> 4478.4946 | P24: =M24/0.186 -> 1447548.4
A25: 2026 | B25: 5000000 | D25: 231.8% | E25: 219226 | F25: 1000000 | G25: 301.2% | H25: 4.4% | I25: 20.0%

Sheet 2019
A1: Name | B1: Salary | C1: https://www.spotrac.com/wnba/rankings/player/_/year/2019/sort/cap_base
A2: DeWanna Bonner | B2: 127500
A3: Sue Bird | B3: 117500
A4: Tina Charles | B4: 117500
A5: Skylar Diggins | B5: 117500
A6: Candice Dupree | B6: 117500
A7: Briann January | B7: 117500
A8: Glory Johnson | B8: 117500
A9: Jewell Loyd | B9: 117500
A10: Angel McCoughtry | B10: 117500
A11: Emma Meesseman | B11: 117500
A12: Chiney Ogwumike | B12: 117500
A13: Candace Parker | B13: 117500
... A156: Shey Peddy | B156: 2723

Sheet 2020
A1: Player | B1: Team | C1: Salary | D1: https://www.spotrac.com/wnba/rankings/player/_/year/2020/team/was/sort/cap_base
A2: DeWanna Bonner | B2: CON | C2: 215000
A3: Skylar Diggins | B3: PHX | C3: 215000
A4: Brittney Griner | B4: PHX | C4: 215000
A5: Sue Bird | B5: SEA | C5: 215000
A6: Elena Delle Donne | B6: WAS | C6: 215000
A7: Emma Meesseman | B7: WAS | C7: 215000
A8: Courtney Vandersloot | B8: CHI | C8: 206000
A9: Allie Quigley | B9: CHI | C9: 200000
A10: Jazmine Jones | B10: NY | C10: 196378
A11: Chelsea Gray | B11: LA | C11: 195000
A12: Courtney Williams | B12: ATL | C12: 185000
A13: Jonquel Jones | B13: CON | C13: 185000
... A171: Emma Cannon | B171: LV | C171: 4560

Sheet 2021
A1: Player | B1: Salary | C1: https://herhoopstats.com/salary-cap-sheet/wnba/players/salary_2021/stats_2021/?stats_to_show=per_game&stat_to_show=pts_per_game
A2: Sue Bird | B2: 221450
A3: DeWanna Bonner | B3: 221450
A4: Liz Cambage | B4: 221450
A5: Elena Delle Donne | B5: 221450
A6: Skylar Diggins | B6: 221450
A7: Brittney Griner | B7: 221450
A8: Diana Taurasi | B8: 221450
A9: Natasha Howard | B9: 215000
A10: Betnijah Laney-Hamilton | B10: 209550
A11: Alyssa Thomas | B11: 200000
A12: Courtney Vandersloot | B12: 200000
A13: Allie Quigley | B13: 194000
... A25: Candace Parker | B25: 190000
A26: Odyssey Sims | B26: =111520+75000 -> 186520
A27: Cheyenne Parker-Tyus | B27: 185000
A28: Jasmine Thomas | B28: 185000
A29: Erica Wheeler | B29: 180000
A30: Candice Dupree | B30: =142000+36541 -> 178541
A31: Astou Ndour-Fall | B31: =108421+70040 -> 178461
A32: Moriah Jefferson | B32: 175100
A33: Shekinna Stricklen | B33: 175100
A34: Tina Charles | B34: 175000
A35: Stefanie Dolson | B35: 175000
A36: Jantel Lavender | B36: 175000
A37: Kelsey Plum | B37: 175000
A38: Layshia Clarendon | B38: =120000+33914+17694 -> 171608
A39: Kahleah Copper | B39: 165000
A40: Natalie Achonwa | B40: 164500
A41: Allisha Gray | B41: 160000
A42: Danielle Robinson | B42: 155000
A43: Isabelle Harrison | B43: 154500
A44: Dearica Hamby | B44: 152300
A45: Sami Whitcomb | B45: 150350
A46: Jessica Breland | B46: 145000
A47: Tiffany Mitchell | B47: 144200
A48: Tianna Hawkins | B48: 140000
A49: Amanda Zahui B. | B49: 135000
A50: Damiris Dantas | B50: 126000
... A64: Kayla Thornton | B64: 89200
...

Sheet 2022
A1: Player | B1: Salary | C1: https://herhoopstats.com/salary-cap-sheet/wnba/players/salary_2022/stats_2022/
A2: Moriah Jefferson | B2: 228094
A3: Breanna Stewart | B3: 228094
A4: Diana Taurasi | B4: 228094
A5: Jewell Loyd | B5: 228094
A6: Skylar Diggins | B6: 227900
A7: Elena Delle Donne | B7: 227900
A8: DeWanna Bonner | B8: 227900
A9: Brittney Griner | B9: 227900
A10: Natasha Howard | B10: 221450
A11: Tiffany Hayes | B11: 215000
A12: Chelsea Gray | B12: 206267
A13: Alyssa Thomas | B13: 206000
... A169: Raina Perez | B169: 2245

Sheet 2023
A1: Team | B1: Name | C1: Salary | D1: https://herhoopstats.com/salary-cap-sheet/wnba/team/2025/minnesota-lynx-11eaecc7-357c-772c-b611-2362f5011b0b/
A2: IND | B2: Erica Wheeler | C2: 242154
A3: DAL | B3: Arike Ogunbowale | C3: 234936
A4: PHX | B4: Diana Taurasi | C4: 234936
A5: SEA | B5: Jewell Loyd | C5: 234936
A6: CON | B6: DeWanna Bonner | C6: 234350
A7: PHX | B7: Skylar Diggins | C7: 234350
A8: WAS | B8: Elena Delle Donne | C8: 234350
A9: DAL | B9: Natasha Howard | C9: 227900
A10: ATL | B10: Cheyenne Parker-Tyus | C10: 216100
A11: CON | B11: Alyssa Thomas | C11: 212000
A12: NY | B12: Jonquel Jones | C12: 211150
A13: CON | B13: Brionna Jones | C13: 208000
... A145: PHX | B145: Christyn Williams | C145: 1625

Sheet 2024
A1: Team | B1: Name | C1: Salary | D1: https://herhoopstats.com/salary-cap-sheet/wnba/team/2024/washington-mystics-11eaecc7-3568-d154-b611-2362f5011b0b/
A2: DAL | B2: Arike Ogunbowale | C2: 241984
A3: PHX | B3: Kahleah Copper | C3: 241984
A4: SEA | B4: Jewell Loyd | C4: 241984
A5: PHX | B5: Diana Taurasi | C5: 234936
A6: DAL | B6: Natasha Howard | C6: 234350
A7: LV | B7: A'ja Wilson | C7: 227303
A8: CON | B8: Alyssa Thomas | C8: 218000
A9: CON | B9: Marina Mabrey | C9: 217592
A10: MIN | B10: Napheesa Collier | C10: 215469
A11: LA | B11: Azurá Stevens | C11: 215000
A12: SEA | B12: Nneka Ogwumike | C12: 214500
A13: CON | B13: Brionna Jones | C13: 212000
... A146: PHX | B146: Amy Atwell | C146: 635

Sheet 2025
A1: Name | B1: Team | C1: Salary | D1: Adjusted Salary | E1: https://herhoopstats.com/salary-cap-sheet/wnba/team/2025/minnesota-lynx-11eaecc7-357c-772c-b611-2362f5011b0b/
A2: Kelsey Mitchell | B2: IND | C2: 269244 | D2: =C2*2.2 -> 592336.8
A3: Jewell Loyd | B3: LV | C3: 249032 | D3: =C3*2.2 -> 547870.4 | E3: =AVERAGE(C2:C164) -> 103772.6
A4: Arike Ogunbowale | B4: DAL | C4: 249032 | D4: =C4*2.2 -> 547870.4
A5: Kahleah Copper | B5: PHX | C5: 248134 | D5: =C5*2.2 -> 545894.8
A6: Gabby Williams | B6: SEA | C6: 225000 | D6: =C6*2.2 -> 495000
A7: Ariel Atkins | B7: CHI | C7: 223000 | D7: =C7*2.2 -> 490600
A8: Breanna Stewart | B8: NY | C8: 222400 | D8: =C8*2.2 -> 489280
A9: Sabrina Ionescu | B9: NY | C9: 222060 | D9: =C9*2.2 -> 488532
A10: Satou Sabally | B10: PHX | C10: 215000 | D10: =C10*2.2 -> 473000
A11: Alyssa Thomas | B11: PHX | C11: 215000 | D11: =C11*2.2 -> 473000
A12: Brittney Griner | B12: ATL | C12: 214466 | D12: =C12*2.2 -> 471825.2
A13: Brionna Jones | B13: ATL | C13: 214466 | D13: =C13*2.2 -> 471825.2
A14: Natasha Howard | B14: IND | C14: 214466 | D14: =C14*2.2 -> 471825.2
A15: Skylar Diggins | B15: SEA | C15: 214466 | D15: =C15*2.2 -> 471825.2
... A164: Christyn Williams | B164: DAL | C164: 833 | D164: =C164*2.2 -> 1832.6
